<sdf version='1.7'>
  <model name='crazyflie2'>
    <link name='crazyflie2/base_link'>
      <inertial>
        <pose>0 0 0 0 -0 0</pose>
        <mass>0.025</mass>
        <inertia>
          <ixx>1.65717e-05</ixx>
          <ixy>0</ixy>
          <ixz>0</ixz>
          <iyy>1.65717e-05</iyy>
          <iyz>0</iyz>
          <izz>2.92617e-05</izz>
        </inertia>
      </inertial>
      <collision name='crazyflie2/base_link_inertia_collision'>
        <pose>0 0 0 0 -0 0</pose>
        <geometry>
          <box>
            <size>0.045 0.045 0.03</size>
          </box>
        </geometry>
      </collision>
      <visual name='crazyflie2/base_link_inertia_visual'>
        <pose>0 0 0 0 -0 0</pose>
        <geometry>
          <mesh>
            <scale>1 1 1</scale>
            <uri>/home/kiko-hp-omen/RoboticPark/src/uned_crazyflie_ros_pkg/uned_crazyflie_config/model/test/crazyflie2.dae</uri>
          </mesh>
        </geometry>
      </visual>
    </link>
    <joint name='crazyflie2/imugt_joint' type='revolute'>
      <pose relative_to='crazyflie2/base_link'>0 0 0 0 -0 0</pose>
      <parent>crazyflie2/base_link</parent>
      <child>crazyflie2/imugt_link</child>
      <axis>
        <xyz>1 0 0</xyz>
        <limit>
          <lower>0</lower>
          <upper>0</upper>
          <effort>0</effort>
          <velocity>0</velocity>
        </limit>
        <dynamics>
          <spring_reference>0</spring_reference>
          <spring_stiffness>0</spring_stiffness>
        </dynamics>
      </axis>
    </joint>
    <link name='crazyflie2/imugt_link'>
      <pose relative_to='crazyflie2/imugt_joint'>0 0 0 0 -0 0</pose>
      <inertial>
        <pose>0 0 0 0 -0 0</pose>
        <mass>1e-05</mass>
        <inertia>
          <ixx>1e-05</ixx>
          <ixy>0</ixy>
          <ixz>0</ixz>
          <iyy>1e-05</iyy>
          <iyz>0</iyz>
          <izz>1e-05</izz>
        </inertia>
      </inertial>
    </link>
    <joint name='crazyflie2/odometry_sensor_joint' type='revolute'>
      <pose relative_to='crazyflie2/base_link'>0 0 0 0 -0 0</pose>
      <parent>crazyflie2/base_link</parent>
      <child>crazyflie2/odometry_sensor_link</child>
      <axis>
        <xyz>1 0 0</xyz>
        <limit>
          <lower>0</lower>
          <upper>0</upper>
          <effort>0</effort>
          <velocity>0</velocity>
        </limit>
        <dynamics>
          <spring_reference>0</spring_reference>
          <spring_stiffness>0</spring_stiffness>
        </dynamics>
      </axis>
    </joint>
    <link name='crazyflie2/odometry_sensor_link'>
      <pose relative_to='crazyflie2/odometry_sensor_joint'>0 0 0 0 -0 0</pose>
      <inertial>
        <pose>0 0 0 0 -0 0</pose>
        <mass>1e-05</mass>
        <inertia>
          <ixx>1e-05</ixx>
          <ixy>0</ixy>
          <ixz>0</ixz>
          <iyy>1e-05</iyy>
          <iyz>0</iyz>
          <izz>1e-05</izz>
        </inertia>
      </inertial>
    </link>
    <joint name='crazyflie2/odometry_sensorgt_joint' type='revolute'>
      <pose relative_to='crazyflie2/base_link'>0 0 0 0 -0 0</pose>
      <parent>crazyflie2/base_link</parent>
      <child>crazyflie2/odometry_sensorgt_link</child>
      <axis>
        <xyz>1 0 0</xyz>
        <limit>
          <lower>0</lower>
          <upper>0</upper>
          <effort>0</effort>
          <velocity>0</velocity>
        </limit>
        <dynamics>
          <spring_reference>0</spring_reference>
          <spring_stiffness>0</spring_stiffness>
        </dynamics>
      </axis>
    </joint>
    <link name='crazyflie2/odometry_sensorgt_link'>
      <pose relative_to='crazyflie2/odometry_sensorgt_joint'>0 0 0 0 -0 0</pose>
      <inertial>
        <pose>0 0 0 0 -0 0</pose>
        <mass>1e-05</mass>
        <inertia>
          <ixx>1e-05</ixx>
          <ixy>0</ixy>
          <ixz>0</ixz>
          <iyy>1e-05</iyy>
          <iyz>0</iyz>
          <izz>1e-05</izz>
        </inertia>
      </inertial>
    </link>
    <joint name='crazyflie2/rotor_0_joint' type='revolute'>
      <pose relative_to='crazyflie2/base_link'>0.032527 -0.032527 0.024 0 -0 0</pose>
      <parent>crazyflie2/base_link</parent>
      <child>crazyflie2/rotor_0</child>
      <axis>
        <xyz>0 0 1</xyz>
        <limit>
          <lower>-1e+16</lower>
          <upper>1e+16</upper>
        </limit>
        <dynamics>
          <spring_reference>0</spring_reference>
          <spring_stiffness>0</spring_stiffness>
        </dynamics>
      </axis>
    </joint>
    <link name='crazyflie2/rotor_0'>
      <pose relative_to='crazyflie2/rotor_0_joint'>0 0 0 0 -0 0</pose>
      <inertial>
        <pose>0 0 0 0 -0 0</pose>
        <mass>0.0005</mass>
        <inertia>
          <ixx>1.20833e-07</ixx>
          <ixy>0</ixy>
          <ixz>0</ixz>
          <iyy>1.07344e-06</iyy>
          <iyz>0</iyz>
          <izz>1.15677e-06</izz>
        </inertia>
      </inertial>
      <collision name='crazyflie2/rotor_0_collision'>
        <pose>0 0 0 0 -0 0</pose>
        <geometry>
          <cylinder>
            <length>0.005</length>
            <radius>0.0225</radius>
          </cylinder>
        </geometry>
        <surface>
          <contact>
            <ode/>
          </contact>
          <friction>
            <ode/>
          </friction>
        </surface>
      </collision>
      <visual name='crazyflie2/rotor_0_visual'>
        <pose>0 0 0 0 -0 0</pose>
        <geometry>
          <mesh>
            <scale>0.0225 0.0225 0.0225</scale>
            <uri>model://rotors_description/meshes/propeller_ccw.dae</uri>
          </mesh>
        </geometry>
        <material>
          <script>
            <name>Gazebo/Red</name>
            <uri>file://media/materials/scripts/gazebo.material</uri>
          </script>
        </material>
      </visual>
      <gravity>1</gravity>
      <velocity_decay/>
    </link>
    <joint name='crazyflie2/rotor_1_joint' type='revolute'>
      <pose relative_to='crazyflie2/base_link'>-0.032527 -0.032527 0.024 0 -0 0</pose>
      <parent>crazyflie2/base_link</parent>
      <child>crazyflie2/rotor_1</child>
      <axis>
        <xyz>0 0 1</xyz>
        <limit>
          <lower>-1e+16</lower>
          <upper>1e+16</upper>
        </limit>
        <dynamics>
          <spring_reference>0</spring_reference>
          <spring_stiffness>0</spring_stiffness>
        </dynamics>
      </axis>
    </joint>
    <link name='crazyflie2/rotor_1'>
      <pose relative_to='crazyflie2/rotor_1_joint'>0 0 0 0 -0 0</pose>
      <inertial>
        <pose>0 0 0 0 -0 0</pose>
        <mass>0.0005</mass>
        <inertia>
          <ixx>1.20833e-07</ixx>
          <ixy>0</ixy>
          <ixz>0</ixz>
          <iyy>1.07344e-06</iyy>
          <iyz>0</iyz>
          <izz>1.15677e-06</izz>
        </inertia>
      </inertial>
      <collision name='crazyflie2/rotor_1_collision'>
        <pose>0 0 0 0 -0 0</pose>
        <geometry>
          <cylinder>
            <length>0.005</length>
            <radius>0.0225</radius>
          </cylinder>
        </geometry>
        <surface>
          <contact>
            <ode/>
          </contact>
          <friction>
            <ode/>
          </friction>
        </surface>
      </collision>
      <visual name='crazyflie2/rotor_1_visual'>
        <pose>0 0 0 0 -0 0</pose>
        <geometry>
          <mesh>
            <scale>0.0225 0.0225 0.0225</scale>
            <uri>model://rotors_description/meshes/propeller_cw.dae</uri>
          </mesh>
        </geometry>
        <material>
          <script>
            <name>Gazebo/Blue</name>
            <uri>file://media/materials/scripts/gazebo.material</uri>
          </script>
        </material>
      </visual>
      <gravity>1</gravity>
      <velocity_decay/>
    </link>
    <joint name='crazyflie2/rotor_2_joint' type='revolute'>
      <pose relative_to='crazyflie2/base_link'>-0.032527 0.032527 0.024 0 -0 0</pose>
      <parent>crazyflie2/base_link</parent>
      <child>crazyflie2/rotor_2</child>
      <axis>
        <xyz>0 0 1</xyz>
        <limit>
          <lower>-1e+16</lower>
          <upper>1e+16</upper>
        </limit>
        <dynamics>
          <spring_reference>0</spring_reference>
          <spring_stiffness>0</spring_stiffness>
        </dynamics>
      </axis>
    </joint>
    <link name='crazyflie2/rotor_2'>
      <pose relative_to='crazyflie2/rotor_2_joint'>0 0 0 0 -0 0</pose>
      <inertial>
        <pose>0 0 0 0 -0 0</pose>
        <mass>0.0005</mass>
        <inertia>
          <ixx>1.20833e-07</ixx>
          <ixy>0</ixy>
          <ixz>0</ixz>
          <iyy>1.07344e-06</iyy>
          <iyz>0</iyz>
          <izz>1.15677e-06</izz>
        </inertia>
      </inertial>
      <collision name='crazyflie2/rotor_2_collision'>
        <pose>0 0 0 0 -0 0</pose>
        <geometry>
          <cylinder>
            <length>0.005</length>
            <radius>0.0225</radius>
          </cylinder>
        </geometry>
        <surface>
          <contact>
            <ode/>
          </contact>
          <friction>
            <ode/>
          </friction>
        </surface>
      </collision>
      <visual name='crazyflie2/rotor_2_visual'>
        <pose>0 0 0 0 -0 0</pose>
        <geometry>
          <mesh>
            <scale>0.0225 0.0225 0.0225</scale>
            <uri>model://rotors_description/meshes/propeller_ccw.dae</uri>
          </mesh>
        </geometry>
        <material>
          <script>
            <name>Gazebo/Blue</name>
            <uri>file://media/materials/scripts/gazebo.material</uri>
          </script>
        </material>
      </visual>
      <gravity>1</gravity>
      <velocity_decay/>
    </link>
    <joint name='crazyflie2/rotor_3_joint' type='revolute'>
      <pose relative_to='crazyflie2/base_link'>0.032527 0.032527 0.024 0 -0 0</pose>
      <parent>crazyflie2/base_link</parent>
      <child>crazyflie2/rotor_3</child>
      <axis>
        <xyz>0 0 1</xyz>
        <limit>
          <lower>-1e+16</lower>
          <upper>1e+16</upper>
        </limit>
        <dynamics>
          <spring_reference>0</spring_reference>
          <spring_stiffness>0</spring_stiffness>
        </dynamics>
      </axis>
    </joint>
    <link name='crazyflie2/rotor_3'>
      <pose relative_to='crazyflie2/rotor_3_joint'>0 0 0 0 -0 0</pose>
      <inertial>
        <pose>0 0 0 0 -0 0</pose>
        <mass>0.0005</mass>
        <inertia>
          <ixx>1.20833e-07</ixx>
          <ixy>0</ixy>
          <ixz>0</ixz>
          <iyy>1.07344e-06</iyy>
          <iyz>0</iyz>
          <izz>1.15677e-06</izz>
        </inertia>
      </inertial>
      <collision name='crazyflie2/rotor_3_collision'>
        <pose>0 0 0 0 -0 0</pose>
        <geometry>
          <cylinder>
            <length>0.005</length>
            <radius>0.0225</radius>
          </cylinder>
        </geometry>
        <surface>
          <contact>
            <ode/>
          </contact>
          <friction>
            <ode/>
          </friction>
        </surface>
      </collision>
      <visual name='crazyflie2/rotor_3_visual'>
        <pose>0 0 0 0 -0 0</pose>
        <geometry>
          <mesh>
            <scale>0.0225 0.0225 0.0225</scale>
            <uri>model://rotors_description/meshes/propeller_cw.dae</uri>
          </mesh>
        </geometry>
        <material>
          <script>
            <name>Gazebo/Red</name>
            <uri>file://media/materials/scripts/gazebo.material</uri>
          </script>
        </material>
      </visual>
      <gravity>1</gravity>
      <velocity_decay/>
    </link>
    <plugin name='multirotor_base_plugin' filename='librotors_gazebo_multirotor_base_plugin.so'>
      <robotNamespace>crazyflie2</robotNamespace>
      <linkName>crazyflie2/base_link</linkName>
      <rotorVelocitySlowdownSim>50</rotorVelocitySlowdownSim>
    </plugin>
    <plugin name='crazyflie2_front-right_motor_model' filename='librotors_gazebo_motor_model.so'>
      <robotNamespace>crazyflie2</robotNamespace>
      <jointName>crazyflie2/rotor_0_joint</jointName>
      <linkName>crazyflie2/rotor_0</linkName>
      <turningDirection>ccw</turningDirection>
      <timeConstantUp>0.0125</timeConstantUp>
      <timeConstantDown>0.025</timeConstantDown>
      <maxRotVelocity>2618</maxRotVelocity>
      <motorConstant>1.28192e-08</motorConstant>
      <momentConstant>0.005964552</momentConstant>
      <commandSubTopic>gazebo/command/motor_speed</commandSubTopic>
      <motorNumber>0</motorNumber>
      <rotorDragCoefficient>8.06428e-05</rotorDragCoefficient>
      <rollingMomentCoefficient>1e-06</rollingMomentCoefficient>
      <motorSpeedPubTopic>motor_speed/0</motorSpeedPubTopic>
      <rotorVelocitySlowdownSim>50</rotorVelocitySlowdownSim>
    </plugin>
    <plugin name='crazyflie2_back-right_motor_model' filename='librotors_gazebo_motor_model.so'>
      <robotNamespace>crazyflie2</robotNamespace>
      <jointName>crazyflie2/rotor_1_joint</jointName>
      <linkName>crazyflie2/rotor_1</linkName>
      <turningDirection>cw</turningDirection>
      <timeConstantUp>0.0125</timeConstantUp>
      <timeConstantDown>0.025</timeConstantDown>
      <maxRotVelocity>2618</maxRotVelocity>
      <motorConstant>1.28192e-08</motorConstant>
      <momentConstant>0.005964552</momentConstant>
      <commandSubTopic>gazebo/command/motor_speed</commandSubTopic>
      <motorNumber>1</motorNumber>
      <rotorDragCoefficient>8.06428e-05</rotorDragCoefficient>
      <rollingMomentCoefficient>1e-06</rollingMomentCoefficient>
      <motorSpeedPubTopic>motor_speed/1</motorSpeedPubTopic>
      <rotorVelocitySlowdownSim>50</rotorVelocitySlowdownSim>
    </plugin>
    <plugin name='crazyflie2_back-left_motor_model' filename='librotors_gazebo_motor_model.so'>
      <robotNamespace>crazyflie2</robotNamespace>
      <jointName>crazyflie2/rotor_2_joint</jointName>
      <linkName>crazyflie2/rotor_2</linkName>
      <turningDirection>ccw</turningDirection>
      <timeConstantUp>0.0125</timeConstantUp>
      <timeConstantDown>0.025</timeConstantDown>
      <maxRotVelocity>2618</maxRotVelocity>
      <motorConstant>1.28192e-08</motorConstant>
      <momentConstant>0.005964552</momentConstant>
      <commandSubTopic>gazebo/command/motor_speed</commandSubTopic>
      <motorNumber>2</motorNumber>
      <rotorDragCoefficient>8.06428e-05</rotorDragCoefficient>
      <rollingMomentCoefficient>1e-06</rollingMomentCoefficient>
      <motorSpeedPubTopic>motor_speed/2</motorSpeedPubTopic>
      <rotorVelocitySlowdownSim>50</rotorVelocitySlowdownSim>
    </plugin>
    <plugin name='crazyflie2_front-left_motor_model' filename='librotors_gazebo_motor_model.so'>
      <robotNamespace>crazyflie2</robotNamespace>
      <jointName>crazyflie2/rotor_3_joint</jointName>
      <linkName>crazyflie2/rotor_3</linkName>
      <turningDirection>cw</turningDirection>
      <timeConstantUp>0.0125</timeConstantUp>
      <timeConstantDown>0.025</timeConstantDown>
      <maxRotVelocity>2618</maxRotVelocity>
      <motorConstant>1.28192e-08</motorConstant>
      <momentConstant>0.005964552</momentConstant>
      <commandSubTopic>gazebo/command/motor_speed</commandSubTopic>
      <motorNumber>3</motorNumber>
      <rotorDragCoefficient>8.06428e-05</rotorDragCoefficient>
      <rollingMomentCoefficient>1e-06</rollingMomentCoefficient>
      <motorSpeedPubTopic>motor_speed/3</motorSpeedPubTopic>
      <rotorVelocitySlowdownSim>50</rotorVelocitySlowdownSim>
    </plugin>
    <plugin name='controller_interface' filename='librotors_gazebo_controller_interface.so'>
      <robotNamespace>crazyflie2</robotNamespace>
      <commandAttitudeThrustSubTopic>command/attitude</commandAttitudeThrustSubTopic>
      <commandRateThrustSubTopic>command/rate</commandRateThrustSubTopic>
      <commandMotorSpeedSubTopic>command/motor_speed</commandMotorSpeedSubTopic>
      <imuSubTopic>imu</imuSubTopic>
      <motorSpeedCommandPubTopic>gazebo/command/motor_speed</motorSpeedCommandPubTopic>
    </plugin>
    <plugin name='odometry_sensor' filename='librotors_gazebo_odometry_plugin.so'>
      <linkName>crazyflie2/odometry_sensor_link</linkName>
      <robotNamespace>crazyflie2</robotNamespace>
      <poseTopic>pose</poseTopic>
      <poseWithCovarianceTopic>pose_with_covariance</poseWithCovarianceTopic>
      <positionTopic>position</positionTopic>
      <transformTopic>transform</transformTopic>
      <odometryTopic>odometry</odometryTopic>
      <parentFrameId>world</parentFrameId>
      <childFrameId>crazyflie2/base_link</childFrameId>
      <measurementDivisor>1</measurementDivisor>
      <measurementDelay>0</measurementDelay>
      <unknownDelay>0.0</unknownDelay>
      <noiseNormalPosition>0 0 0</noiseNormalPosition>
      <noiseNormalQuaternion>0 0 0</noiseNormalQuaternion>
      <noiseNormalLinearVelocity>0 0 0</noiseNormalLinearVelocity>
      <noiseNormalAngularVelocity>0 0 0</noiseNormalAngularVelocity>
      <noiseUniformPosition>0 0 0</noiseUniformPosition>
      <noiseUniformQuaternion>0 0 0</noiseUniformQuaternion>
      <noiseUniformLinearVelocity>0 0 0</noiseUniformLinearVelocity>
      <noiseUniformAngularVelocity>0 0 0</noiseUniformAngularVelocity>
    </plugin>
    <plugin name='rotors_gazebo_imugt_plugin' filename='librotors_gazebo_imu_plugin.so'>
      <robotNamespace>crazyflie2</robotNamespace>
      <linkName>crazyflie2/imugt_link</linkName>
      <imuTopic>ground_truth/imu</imuTopic>
      <gyroscopeNoiseDensity>0.0</gyroscopeNoiseDensity>
      <measurementDivisor>1</measurementDivisor>
      <measurementDelay>0</measurementDelay>
      <gyroscopeRandomWalk>0.0</gyroscopeRandomWalk>
      <gyroscopeBiasCorrelationTime>1000.0</gyroscopeBiasCorrelationTime>
      <gyroscopeTurnOnBiasSigma>0.0</gyroscopeTurnOnBiasSigma>
      <accelerometerNoiseDensity>0.0</accelerometerNoiseDensity>
      <accelerometerRandomWalk>0.0</accelerometerRandomWalk>
      <accelerometerBiasCorrelationTime>300.0</accelerometerBiasCorrelationTime>
      <accelerometerTurnOnBiasSigma>0.0</accelerometerTurnOnBiasSigma>
    </plugin>
    <static>0</static>
    <plugin name='odometry_sensorgt' filename='librotors_gazebo_odometry_plugin.so'>
      <linkName>crazyflie2/odometry_sensorgt_link</linkName>
      <robotNamespace>crazyflie2</robotNamespace>
      <poseTopic>ground_truth/pose</poseTopic>
      <poseWithCovarianceTopic>ground_truth/pose_with_covariance</poseWithCovarianceTopic>
      <positionTopic>ground_truth/position</positionTopic>
      <transformTopic>ground_truth/transform</transformTopic>
      <odometryTopic>ground_truth/odometry</odometryTopic>
      <parentFrameId>world</parentFrameId>
      <childFrameId>crazyflie2/base_link</childFrameId>
      <measurementDivisor>1</measurementDivisor>
      <measurementDelay>0</measurementDelay>
      <unknownDelay>0.0</unknownDelay>
      <noiseNormalPosition>0 0 0</noiseNormalPosition>
      <noiseNormalQuaternion>0 0 0</noiseNormalQuaternion>
      <noiseNormalLinearVelocity>0 0 0</noiseNormalLinearVelocity>
      <noiseNormalAngularVelocity>0 0 0</noiseNormalAngularVelocity>
      <noiseUniformPosition>0 0 0</noiseUniformPosition>
      <noiseUniformQuaternion>0 0 0</noiseUniformQuaternion>
      <noiseUniformLinearVelocity>0 0 0</noiseUniformLinearVelocity>
      <noiseUniformAngularVelocity>0 0 0</noiseUniformAngularVelocity>
    </plugin>
  </model>
</sdf>
